2019-08-16 15:21:10,484: Exception on /login [POST] [in /home/yuz/.local/lib/python3.5/site-packages/flask/app.py:1780]
Traceback (most recent call last):
  File "/home/yuz/.local/lib/python3.5/site-packages/pymysql/connections.py", line 583, in connect
    **kwargs)
  File "/usr/lib/python3.5/socket.py", line 711, in create_connection
    raise err
  File "/usr/lib/python3.5/socket.py", line 702, in create_connection
    sock.connect(sa)
ConnectionRefusedError: [Errno 111] Connection refused

During handling of the above exception, another exception occurred:

Traceback (most recent call last):
  File "/home/yuz/.local/lib/python3.5/site-packages/sqlalchemy/engine/base.py", line 2262, in _wrap_pool_connect
    return fn()
  File "/home/yuz/.local/lib/python3.5/site-packages/sqlalchemy/pool/base.py", line 363, in connect
    return _ConnectionFairy._checkout(self)
  File "/home/yuz/.local/lib/python3.5/site-packages/sqlalchemy/pool/base.py", line 760, in _checkout
    fairy = _ConnectionRecord.checkout(pool)
  File "/home/yuz/.local/lib/python3.5/site-packages/sqlalchemy/pool/base.py", line 492, in checkout
    rec = pool._do_get()
  File "/home/yuz/.local/lib/python3.5/site-packages/sqlalchemy/pool/impl.py", line 139, in _do_get
    self._dec_overflow()
  File "/home/yuz/.local/lib/python3.5/site-packages/sqlalchemy/util/langhelpers.py", line 68, in __exit__
    compat.reraise(exc_type, exc_value, exc_tb)
  File "/home/yuz/.local/lib/python3.5/site-packages/sqlalchemy/util/compat.py", line 129, in reraise
    raise value
  File "/home/yuz/.local/lib/python3.5/site-packages/sqlalchemy/pool/impl.py", line 136, in _do_get
    return self._create_connection()
  File "/home/yuz/.local/lib/python3.5/site-packages/sqlalchemy/pool/base.py", line 308, in _create_connection
    return _ConnectionRecord(self)
  File "/home/yuz/.local/lib/python3.5/site-packages/sqlalchemy/pool/base.py", line 437, in __init__
    self.__connect(first_connect_check=True)
  File "/home/yuz/.local/lib/python3.5/site-packages/sqlalchemy/pool/base.py", line 639, in __connect
    connection = pool._invoke_creator(self)
  File "/home/yuz/.local/lib/python3.5/site-packages/sqlalchemy/engine/strategies.py", line 114, in connect
    return dialect.connect(*cargs, **cparams)
  File "/home/yuz/.local/lib/python3.5/site-packages/sqlalchemy/engine/default.py", line 453, in connect
    return self.dbapi.connect(*cargs, **cparams)
  File "/home/yuz/.local/lib/python3.5/site-packages/pymysql/__init__.py", line 94, in Connect
    return Connection(*args, **kwargs)
  File "/home/yuz/.local/lib/python3.5/site-packages/pymysql/connections.py", line 325, in __init__
    self.connect()
  File "/home/yuz/.local/lib/python3.5/site-packages/pymysql/connections.py", line 630, in connect
    raise exc
pymysql.err.OperationalError: (2003, "Can't connect to MySQL server on 'localhost' ([Errno 111] Connection refused)")

The above exception was the direct cause of the following exception:

Traceback (most recent call last):
  File "/home/yuz/.local/lib/python3.5/site-packages/flask/app.py", line 2311, in wsgi_app
    response = self.full_dispatch_request()
  File "/home/yuz/.local/lib/python3.5/site-packages/flask/app.py", line 1834, in full_dispatch_request
    rv = self.handle_user_exception(e)
  File "/home/yuz/.local/lib/python3.5/site-packages/flask/app.py", line 1737, in handle_user_exception
    reraise(exc_type, exc_value, tb)
  File "/home/yuz/.local/lib/python3.5/site-packages/flask/_compat.py", line 36, in reraise
    raise value
  File "/home/yuz/.local/lib/python3.5/site-packages/flask/app.py", line 1832, in full_dispatch_request
    rv = self.dispatch_request()
  File "/home/yuz/.local/lib/python3.5/site-packages/flask/app.py", line 1818, in dispatch_request
    return self.view_functions[rule.endpoint](**req.view_args)
  File "/mnt/c/data/jianguoyun/subjects/python_dev/dev01_git/app/main/views/user.py", line 50, in login
    user = User.query.filter_by(email=form.email.data).first()
  File "/home/yuz/.local/lib/python3.5/site-packages/sqlalchemy/orm/query.py", line 3215, in first
    ret = list(self[0:1])
  File "/home/yuz/.local/lib/python3.5/site-packages/sqlalchemy/orm/query.py", line 3007, in __getitem__
    return list(res)
  File "/home/yuz/.local/lib/python3.5/site-packages/sqlalchemy/orm/query.py", line 3317, in __iter__
    return self._execute_and_instances(context)
  File "/home/yuz/.local/lib/python3.5/site-packages/sqlalchemy/orm/query.py", line 3339, in _execute_and_instances
    querycontext, self._connection_from_session, close_with_result=True
  File "/home/yuz/.local/lib/python3.5/site-packages/sqlalchemy/orm/query.py", line 3354, in _get_bind_args
    mapper=self._bind_mapper(), clause=querycontext.statement, **kw
  File "/home/yuz/.local/lib/python3.5/site-packages/sqlalchemy/orm/query.py", line 3332, in _connection_from_session
    conn = self.session.connection(**kw)
  File "/home/yuz/.local/lib/python3.5/site-packages/sqlalchemy/orm/session.py", line 1123, in connection
    execution_options=execution_options,
  File "/home/yuz/.local/lib/python3.5/site-packages/sqlalchemy/orm/session.py", line 1129, in _connection_for_bind
    engine, execution_options
  File "/home/yuz/.local/lib/python3.5/site-packages/sqlalchemy/orm/session.py", line 430, in _connection_for_bind
    conn = bind._contextual_connect()
  File "/home/yuz/.local/lib/python3.5/site-packages/sqlalchemy/engine/base.py", line 2226, in _contextual_connect
    self._wrap_pool_connect(self.pool.connect, None),
  File "/home/yuz/.local/lib/python3.5/site-packages/sqlalchemy/engine/base.py", line 2266, in _wrap_pool_connect
    e, dialect, self
  File "/home/yuz/.local/lib/python3.5/site-packages/sqlalchemy/engine/base.py", line 1536, in _handle_dbapi_exception_noconnection
    util.raise_from_cause(sqlalchemy_exception, exc_info)
  File "/home/yuz/.local/lib/python3.5/site-packages/sqlalchemy/util/compat.py", line 383, in raise_from_cause
    reraise(type(exception), exception, tb=exc_tb, cause=cause)
  File "/home/yuz/.local/lib/python3.5/site-packages/sqlalchemy/util/compat.py", line 128, in reraise
    raise value.with_traceback(tb)
  File "/home/yuz/.local/lib/python3.5/site-packages/sqlalchemy/engine/base.py", line 2262, in _wrap_pool_connect
    return fn()
  File "/home/yuz/.local/lib/python3.5/site-packages/sqlalchemy/pool/base.py", line 363, in connect
    return _ConnectionFairy._checkout(self)
  File "/home/yuz/.local/lib/python3.5/site-packages/sqlalchemy/pool/base.py", line 760, in _checkout
    fairy = _ConnectionRecord.checkout(pool)
  File "/home/yuz/.local/lib/python3.5/site-packages/sqlalchemy/pool/base.py", line 492, in checkout
    rec = pool._do_get()
  File "/home/yuz/.local/lib/python3.5/site-packages/sqlalchemy/pool/impl.py", line 139, in _do_get
    self._dec_overflow()
  File "/home/yuz/.local/lib/python3.5/site-packages/sqlalchemy/util/langhelpers.py", line 68, in __exit__
    compat.reraise(exc_type, exc_value, exc_tb)
  File "/home/yuz/.local/lib/python3.5/site-packages/sqlalchemy/util/compat.py", line 129, in reraise
    raise value
  File "/home/yuz/.local/lib/python3.5/site-packages/sqlalchemy/pool/impl.py", line 136, in _do_get
    return self._create_connection()
  File "/home/yuz/.local/lib/python3.5/site-packages/sqlalchemy/pool/base.py", line 308, in _create_connection
    return _ConnectionRecord(self)
  File "/home/yuz/.local/lib/python3.5/site-packages/sqlalchemy/pool/base.py", line 437, in __init__
    self.__connect(first_connect_check=True)
  File "/home/yuz/.local/lib/python3.5/site-packages/sqlalchemy/pool/base.py", line 639, in __connect
    connection = pool._invoke_creator(self)
  File "/home/yuz/.local/lib/python3.5/site-packages/sqlalchemy/engine/strategies.py", line 114, in connect
    return dialect.connect(*cargs, **cparams)
  File "/home/yuz/.local/lib/python3.5/site-packages/sqlalchemy/engine/default.py", line 453, in connect
    return self.dbapi.connect(*cargs, **cparams)
  File "/home/yuz/.local/lib/python3.5/site-packages/pymysql/__init__.py", line 94, in Connect
    return Connection(*args, **kwargs)
  File "/home/yuz/.local/lib/python3.5/site-packages/pymysql/connections.py", line 325, in __init__
    self.connect()
  File "/home/yuz/.local/lib/python3.5/site-packages/pymysql/connections.py", line 630, in connect
    raise exc
sqlalchemy.exc.OperationalError: (pymysql.err.OperationalError) (2003, "Can't connect to MySQL server on 'localhost' ([Errno 111] Connection refused)")
(Background on this error at: http://sqlalche.me/e/e3q8)
2019-08-17 09:13:10,710: Exception on /login [POST] [in D:\data\envs\lemon_platform\lib\site-packages\flask\app.py:1780]
Traceback (most recent call last):
  File "D:\data\envs\lemon_platform\lib\site-packages\pymysql\connections.py", line 583, in connect
    **kwargs)
  File "C:\python37\lib\socket.py", line 727, in create_connection
    raise err
  File "C:\python37\lib\socket.py", line 716, in create_connection
    sock.connect(sa)
ConnectionRefusedError: [WinError 10061] 由于目标计算机积极拒绝，无法连接。

During handling of the above exception, another exception occurred:

Traceback (most recent call last):
  File "D:\data\envs\lemon_platform\lib\site-packages\sqlalchemy\engine\base.py", line 2262, in _wrap_pool_connect
    return fn()
  File "D:\data\envs\lemon_platform\lib\site-packages\sqlalchemy\pool\base.py", line 363, in connect
    return _ConnectionFairy._checkout(self)
  File "D:\data\envs\lemon_platform\lib\site-packages\sqlalchemy\pool\base.py", line 760, in _checkout
    fairy = _ConnectionRecord.checkout(pool)
  File "D:\data\envs\lemon_platform\lib\site-packages\sqlalchemy\pool\base.py", line 492, in checkout
    rec = pool._do_get()
  File "D:\data\envs\lemon_platform\lib\site-packages\sqlalchemy\pool\impl.py", line 139, in _do_get
    self._dec_overflow()
  File "D:\data\envs\lemon_platform\lib\site-packages\sqlalchemy\util\langhelpers.py", line 68, in __exit__
    compat.reraise(exc_type, exc_value, exc_tb)
  File "D:\data\envs\lemon_platform\lib\site-packages\sqlalchemy\util\compat.py", line 129, in reraise
    raise value
  File "D:\data\envs\lemon_platform\lib\site-packages\sqlalchemy\pool\impl.py", line 136, in _do_get
    return self._create_connection()
  File "D:\data\envs\lemon_platform\lib\site-packages\sqlalchemy\pool\base.py", line 308, in _create_connection
    return _ConnectionRecord(self)
  File "D:\data\envs\lemon_platform\lib\site-packages\sqlalchemy\pool\base.py", line 437, in __init__
    self.__connect(first_connect_check=True)
  File "D:\data\envs\lemon_platform\lib\site-packages\sqlalchemy\pool\base.py", line 639, in __connect
    connection = pool._invoke_creator(self)
  File "D:\data\envs\lemon_platform\lib\site-packages\sqlalchemy\engine\strategies.py", line 114, in connect
    return dialect.connect(*cargs, **cparams)
  File "D:\data\envs\lemon_platform\lib\site-packages\sqlalchemy\engine\default.py", line 453, in connect
    return self.dbapi.connect(*cargs, **cparams)
  File "D:\data\envs\lemon_platform\lib\site-packages\pymysql\__init__.py", line 94, in Connect
    return Connection(*args, **kwargs)
  File "D:\data\envs\lemon_platform\lib\site-packages\pymysql\connections.py", line 325, in __init__
    self.connect()
  File "D:\data\envs\lemon_platform\lib\site-packages\pymysql\connections.py", line 630, in connect
    raise exc
pymysql.err.OperationalError: (2003, "Can't connect to MySQL server on 'localhost' ([WinError 10061] 由于目标计算机积极拒绝，无法连接。)")

The above exception was the direct cause of the following exception:

Traceback (most recent call last):
  File "D:\data\envs\lemon_platform\lib\site-packages\flask\app.py", line 2311, in wsgi_app
    response = self.full_dispatch_request()
  File "D:\data\envs\lemon_platform\lib\site-packages\flask\app.py", line 1834, in full_dispatch_request
    rv = self.handle_user_exception(e)
  File "D:\data\envs\lemon_platform\lib\site-packages\flask\app.py", line 1737, in handle_user_exception
    reraise(exc_type, exc_value, tb)
  File "D:\data\envs\lemon_platform\lib\site-packages\flask\_compat.py", line 36, in reraise
    raise value
  File "D:\data\envs\lemon_platform\lib\site-packages\flask\app.py", line 1832, in full_dispatch_request
    rv = self.dispatch_request()
  File "D:\data\envs\lemon_platform\lib\site-packages\flask\app.py", line 1818, in dispatch_request
    return self.view_functions[rule.endpoint](**req.view_args)
  File "C:\data\jianguoyun\subjects\python_dev\dev01_git\app\main\views\user.py", line 50, in login
    user = User.query.filter_by(email=form.email.data).first()
  File "D:\data\envs\lemon_platform\lib\site-packages\sqlalchemy\orm\query.py", line 3215, in first
    ret = list(self[0:1])
  File "D:\data\envs\lemon_platform\lib\site-packages\sqlalchemy\orm\query.py", line 3007, in __getitem__
    return list(res)
  File "D:\data\envs\lemon_platform\lib\site-packages\sqlalchemy\orm\query.py", line 3317, in __iter__
    return self._execute_and_instances(context)
  File "D:\data\envs\lemon_platform\lib\site-packages\sqlalchemy\orm\query.py", line 3339, in _execute_and_instances
    querycontext, self._connection_from_session, close_with_result=True
  File "D:\data\envs\lemon_platform\lib\site-packages\sqlalchemy\orm\query.py", line 3354, in _get_bind_args
    mapper=self._bind_mapper(), clause=querycontext.statement, **kw
  File "D:\data\envs\lemon_platform\lib\site-packages\sqlalchemy\orm\query.py", line 3332, in _connection_from_session
    conn = self.session.connection(**kw)
  File "D:\data\envs\lemon_platform\lib\site-packages\sqlalchemy\orm\session.py", line 1123, in connection
    execution_options=execution_options,
  File "D:\data\envs\lemon_platform\lib\site-packages\sqlalchemy\orm\session.py", line 1129, in _connection_for_bind
    engine, execution_options
  File "D:\data\envs\lemon_platform\lib\site-packages\sqlalchemy\orm\session.py", line 430, in _connection_for_bind
    conn = bind._contextual_connect()
  File "D:\data\envs\lemon_platform\lib\site-packages\sqlalchemy\engine\base.py", line 2226, in _contextual_connect
    self._wrap_pool_connect(self.pool.connect, None),
  File "D:\data\envs\lemon_platform\lib\site-packages\sqlalchemy\engine\base.py", line 2266, in _wrap_pool_connect
    e, dialect, self
  File "D:\data\envs\lemon_platform\lib\site-packages\sqlalchemy\engine\base.py", line 1536, in _handle_dbapi_exception_noconnection
    util.raise_from_cause(sqlalchemy_exception, exc_info)
  File "D:\data\envs\lemon_platform\lib\site-packages\sqlalchemy\util\compat.py", line 383, in raise_from_cause
    reraise(type(exception), exception, tb=exc_tb, cause=cause)
  File "D:\data\envs\lemon_platform\lib\site-packages\sqlalchemy\util\compat.py", line 128, in reraise
    raise value.with_traceback(tb)
  File "D:\data\envs\lemon_platform\lib\site-packages\sqlalchemy\engine\base.py", line 2262, in _wrap_pool_connect
    return fn()
  File "D:\data\envs\lemon_platform\lib\site-packages\sqlalchemy\pool\base.py", line 363, in connect
    return _ConnectionFairy._checkout(self)
  File "D:\data\envs\lemon_platform\lib\site-packages\sqlalchemy\pool\base.py", line 760, in _checkout
    fairy = _ConnectionRecord.checkout(pool)
  File "D:\data\envs\lemon_platform\lib\site-packages\sqlalchemy\pool\base.py", line 492, in checkout
    rec = pool._do_get()
  File "D:\data\envs\lemon_platform\lib\site-packages\sqlalchemy\pool\impl.py", line 139, in _do_get
    self._dec_overflow()
  File "D:\data\envs\lemon_platform\lib\site-packages\sqlalchemy\util\langhelpers.py", line 68, in __exit__
    compat.reraise(exc_type, exc_value, exc_tb)
  File "D:\data\envs\lemon_platform\lib\site-packages\sqlalchemy\util\compat.py", line 129, in reraise
    raise value
  File "D:\data\envs\lemon_platform\lib\site-packages\sqlalchemy\pool\impl.py", line 136, in _do_get
    return self._create_connection()
  File "D:\data\envs\lemon_platform\lib\site-packages\sqlalchemy\pool\base.py", line 308, in _create_connection
    return _ConnectionRecord(self)
  File "D:\data\envs\lemon_platform\lib\site-packages\sqlalchemy\pool\base.py", line 437, in __init__
    self.__connect(first_connect_check=True)
  File "D:\data\envs\lemon_platform\lib\site-packages\sqlalchemy\pool\base.py", line 639, in __connect
    connection = pool._invoke_creator(self)
  File "D:\data\envs\lemon_platform\lib\site-packages\sqlalchemy\engine\strategies.py", line 114, in connect
    return dialect.connect(*cargs, **cparams)
  File "D:\data\envs\lemon_platform\lib\site-packages\sqlalchemy\engine\default.py", line 453, in connect
    return self.dbapi.connect(*cargs, **cparams)
  File "D:\data\envs\lemon_platform\lib\site-packages\pymysql\__init__.py", line 94, in Connect
    return Connection(*args, **kwargs)
  File "D:\data\envs\lemon_platform\lib\site-packages\pymysql\connections.py", line 325, in __init__
    self.connect()
  File "D:\data\envs\lemon_platform\lib\site-packages\pymysql\connections.py", line 630, in connect
    raise exc
sqlalchemy.exc.OperationalError: (pymysql.err.OperationalError) (2003, "Can't connect to MySQL server on 'localhost' ([WinError 10061] 由于目标计算机积极拒绝，无法连接。)")
(Background on this error at: http://sqlalche.me/e/e3q8)
